<?xml version="1.0"?>

<robot name="diff_mobile">
<!-- Link -->
	<link name="base_footprint" />

	<link name="base_link">
   		<visual>
			<origin xyz="0 0 0" rpy="0 0 1.5707963268" />
			<geometry>
				<box size="0.05 0.05 0.02"/>
			</geometry>
			<material name="Aluminum">
				<color rgba="0.9 0.1 0.1 1" />
			</material>
   		</visual>



 	</link>

 	<link name="wheel_l">
   		<visual>
			<origin xyz="0 0 0" rpy="0 1.52 0"/>
     			<geometry>
				<cylinder radius="0.07" length="0.03"/>
			</geometry>
   			<material name="Rubber">
				<color rgba="0.6 0.9 0.9 1"/>
			</material>
		</visual>

 	</link>

 	<link name="wheel_r">
   		<visual>
			<origin xyz="0 0 0" rpy="0 1.52 0"/>
     			<geometry>
				<cylinder radius="0.07" length="0.03"/>
				</geometry>
   			<material name="Rubber">
				<color rgba="0.6 0.9 0.9 1"/>
			</material>
		</visual>
	
 	</link>

	<link name="camera_link">
		<visual>
			<origin xyz="0 0 0" rpy="0 0 0"/>
			<geometry>
				<box size="0.05 0.05 0.02"/>
			</geometry>
			<material name="CameraPlastic">
				<color rgba="0.32 0.63 0.482 1.0"/>
			</material>
		</visual>
	</link>

	<link name="lidar_link">
		<visual>
			<origin xyz="0 0 0" rpy="0 0 0"/>
			<geometry>
				<cylinder radius="0.05" length="0.05"/>
			</geometry>
			<material name="lidarPlastic">
				<color rgba="0.482 0.32 0.63 1.0"/>
			</material>
		</visual>
	</link>
	
<!-- Joint --> 
 	<joint name="base_footprint_to_base_link" type="fixed">
 		<parent link="base_footprint"/>
 		<child link="base_link" />
		<origin xyz="0 0 0.03" rpy="0 0 0"/>
 	</joint>
	
 	<joint name="base_to_wheel_l" type="continuous">
   		<parent link="base_link"/>
   		<child link="wheel_l"/>
   		<origin xyz="0.07 0.16 0.038" rpy="0 0 1.5707963268"/>
		<axis xyz="1 0 0"/>
		<dynamics
			friction="1.0"
			damping="1.0" />
 	</joint>

 	<joint name="base_to_wheel_r" type="continuous">
   		<parent link="base_link"/>
   		<child link="wheel_r"/>
   		<origin xyz="0.07 -0.16 0.038" rpy="0 0 1.5707963268"/>
		<axis xyz="1 0 0"/>
		<dynamics
			friction="1.0"
			damping="1.0" />
 	</joint>
	
	<joint name="base_to_camara" type="fixed">
		<origin xyz="0.17 0 0.145" rpy="0.0 0.0 0.0"/>
		<parent link="base_link"/>
		<child link="camera_link"/>
		<axis xyz="0 0 0"/>
	</joint>

	<joint name="base_to_lidar" type="fixed">
		<origin xyz="0 0 0.2" rpy="0.0 0.0 0.0"/>
		<parent link="base_link"/>
		<child link="lidar_link"/>
		<axis xyz="0 0 0"/>
	</joint>


	<!-- gazebo-->
	<gazebo reference="base_link">
		<mu1>0.1</mu1>
		<mu2>0.1</mu2>
		<material> Gazebo/Red </material>
	</gazebo>

	<gazebo reference="wheel_l">
		<mu1>1.0</mu1>
		<mu2>1.0</mu2>

		<kp>500000.0</kp>
		<kd>10.0</kd>
		<material> Gazebo/Black </material>
	</gazebo>

	<gazebo reference="wheel_r">
		<mu1>1.0</mu1>
		<mu2>1.0</mu2>
		
		<kp>500000.0</kp>
		<kd>10.0</kd>
		<material> Gazebo/Black</material>
	</gazebo>

	<gazebo>
		<plugin name="diff_mobile" filename="libgazebo_ros_diff_drive.so">
			<ros>
			<remapping>cmd_vel:=cmd_vel</remapping>
			<remapping>odom:=odom</remapping>
			</ros>

			<update_rate>20</update_rate>
			<left_joint>base_to_wheel_l</left_joint>
			<right_joint>base_to_wheel_r</right_joint>

			<wheel_separation>0.32</wheel_separation>
			<wheel_diameter>0.20</wheel_diameter>

			<max_wheel_torque>20</max_wheel_torque>
			<max_wheel_accleration>0.5</max_wheel_accleration>

			<command_topic>cmd_vel</command_topic>

			<publish_odom>true</publish_odom>
			<publish_odom_tf>true</publish_odom_tf>
			<publish_wheel_tf>true</publish_wheel_tf>

			<odometry_topic>odom</odometry_topic>
			<odometry_frame>odom</odometry_frame>
			<robot_base_frame>fixed_base</robot_base_frame>
		</plugin>
	</gazebo>

	  <!-- camera -->
	<gazebo reference="camera_link">
		<material>Gazebo/Blue</material>
		<sensor type="camera" name="camera1">
		<update_rate>30.0</update_rate>
		<camera name="head">
			<horizontal_fov>1.3962634</horizontal_fov>
			<image>
			<width>800</width>
			<height>800</height>
			<format>R8G8B8</format>
			</image>
			<clip>
			<near>0.02</near>
			<far>300</far>
			</clip>
			<noise>
			<type>gaussian</type>
			<!-- Noise is sampled independently per pixel on each frame.
				That pixel's noise value is added to each of its color
				channels, which at that point lie in the range [0,1]. -->
			<mean>0.0</mean>
			<stddev>0.007</stddev>
			</noise>
		</camera>
		<plugin name="camera_controller" filename="libgazebo_ros_camera.so">
			<alwaysOn>true</alwaysOn>
			<updateRate>0.0</updateRate>
			<cameraName>rrbot/camera1</cameraName>
			<imageTopicName>image_raw</imageTopicName>
			<cameraInfoTopicName>camera_info</cameraInfoTopicName>
			<frameName>camera_link</frameName>
			<hackBaseline>0.07</hackBaseline>
			<distortionK1>0.0</distortionK1>
			<distortionK2>0.0</distortionK2>
			<distortionK3>0.0</distortionK3>
			<distortionT1>0.0</distortionT1>
			<distortionT2>0.0</distortionT2>
		</plugin>
		</sensor>
	</gazebo>

	<!-- lidar -->
	<gazebo reference="lidar_link">
		<sensor type="ray" name="head_lidar_sensor">
		<pose>0 0 0 0 0 0</pose>
		<visualize>false</visualize>
		<update_rate>100</update_rate>
		<ray>
			<scan>
			<horizontal>
				<samples>720</samples>
				<resolution>1</resolution>
				<min_angle>-3.141592</min_angle>
				<max_angle>3.141592</max_angle>
			</horizontal>
			</scan>
			<range>
			<min>0.10</min>
			<max>15.0</max>
			<resolution>1</resolution>
			</range>
			<noise>
			<type>gaussian</type>
			<!-- Noise parameters based on published spec for Hokuyo laser
				achieving "+-30mm" accuracy at range < 10m.  A mean of 0.0m and
				stddev of 0.01m will put 99.7% of samples within 0.03m of the true
				reading. -->
			<mean>0.0</mean>
			<stddev>0.01</stddev>
			</noise>
		</ray>
		<plugin name="gazebo_ros_head_lidar_controller" filename="libgazebo_ros_ray_sensor.so">
			<ros>
				<argument>~/out:=scan</argument>
			</ros>
			<output_type>sensor_msgs/LaserScan</output_type>
			<frameName>lidar_link</frameName>
		</plugin>
		</sensor>
	</gazebo>


</robot>
